[2025-10-20T16:23:47.898+0000] {taskinstance.py:1083} INFO - Dependencies all met for <TaskInstance: Airflow_Lab1_HeartDisease.load_data manual__2025-10-20T16:23:46.490436+00:00 [queued]>
[2025-10-20T16:23:47.906+0000] {taskinstance.py:1083} INFO - Dependencies all met for <TaskInstance: Airflow_Lab1_HeartDisease.load_data manual__2025-10-20T16:23:46.490436+00:00 [queued]>
[2025-10-20T16:23:47.906+0000] {taskinstance.py:1279} INFO - 
--------------------------------------------------------------------------------
[2025-10-20T16:23:47.906+0000] {taskinstance.py:1280} INFO - Starting attempt 1 of 2
[2025-10-20T16:23:47.907+0000] {taskinstance.py:1281} INFO - 
--------------------------------------------------------------------------------
[2025-10-20T16:23:47.915+0000] {taskinstance.py:1300} INFO - Executing <Task(PythonOperator): load_data> on 2025-10-20 16:23:46.490436+00:00
[2025-10-20T16:23:47.920+0000] {standard_task_runner.py:55} INFO - Started process 85 to run task
[2025-10-20T16:23:47.922+0000] {standard_task_runner.py:82} INFO - Running: ['***', 'tasks', 'run', 'Airflow_Lab1_HeartDisease', 'load_data', 'manual__2025-10-20T16:23:46.490436+00:00', '--job-id', '19', '--raw', '--subdir', 'DAGS_FOLDER/***.py', '--cfg-path', '/tmp/tmpjsyt09he']
[2025-10-20T16:23:47.922+0000] {standard_task_runner.py:83} INFO - Job 19: Subtask load_data
[2025-10-20T16:23:47.969+0000] {task_command.py:388} INFO - Running <TaskInstance: Airflow_Lab1_HeartDisease.load_data manual__2025-10-20T16:23:46.490436+00:00 [running]> on host 4f5dae01acdc
[2025-10-20T16:23:48.006+0000] {taskinstance.py:1509} INFO - Exporting the following env vars:
AIRFLOW_CTX_DAG_OWNER=gnanasudharsan
AIRFLOW_CTX_DAG_ID=Airflow_Lab1_HeartDisease
AIRFLOW_CTX_TASK_ID=load_data
AIRFLOW_CTX_EXECUTION_DATE=2025-10-20T16:23:46.490436+00:00
AIRFLOW_CTX_TRY_NUMBER=1
AIRFLOW_CTX_DAG_RUN_ID=manual__2025-10-20T16:23:46.490436+00:00
[2025-10-20T16:23:48.008+0000] {taskinstance.py:1768} ERROR - Task failed with exception
Traceback (most recent call last):
  File "/home/airflow/.local/lib/python3.7/site-packages/airflow/operators/python.py", line 175, in execute
    return_value = self.execute_callable()
  File "/home/airflow/.local/lib/python3.7/site-packages/airflow/operators/python.py", line 192, in execute_callable
    return self.python_callable(*self.op_args, **self.op_kwargs)
  File "/opt/airflow/dags/src/lab.py", line 13, in load_data
    df = pd.read_csv('/Users/gnanasudharsanashokumar/Downloads/Airflow_Labs/Lab_1/dags/data/heart_disease_uci.csv', header=None, names=columns)
  File "/home/airflow/.local/lib/python3.7/site-packages/pandas/util/_decorators.py", line 311, in wrapper
    return func(*args, **kwargs)
  File "/home/airflow/.local/lib/python3.7/site-packages/pandas/io/parsers/readers.py", line 586, in read_csv
    return _read(filepath_or_buffer, kwds)
  File "/home/airflow/.local/lib/python3.7/site-packages/pandas/io/parsers/readers.py", line 482, in _read
    parser = TextFileReader(filepath_or_buffer, **kwds)
  File "/home/airflow/.local/lib/python3.7/site-packages/pandas/io/parsers/readers.py", line 811, in __init__
    self._engine = self._make_engine(self.engine)
  File "/home/airflow/.local/lib/python3.7/site-packages/pandas/io/parsers/readers.py", line 1040, in _make_engine
    return mapping[engine](self.f, **self.options)  # type: ignore[call-arg]
  File "/home/airflow/.local/lib/python3.7/site-packages/pandas/io/parsers/c_parser_wrapper.py", line 51, in __init__
    self._open_handles(src, kwds)
  File "/home/airflow/.local/lib/python3.7/site-packages/pandas/io/parsers/base_parser.py", line 229, in _open_handles
    errors=kwds.get("encoding_errors", "strict"),
  File "/home/airflow/.local/lib/python3.7/site-packages/pandas/io/common.py", line 707, in get_handle
    newline="",
FileNotFoundError: [Errno 2] No such file or directory: '/Users/gnanasudharsanashokumar/Downloads/Airflow_Labs/Lab_1/dags/data/heart_disease_uci.csv'
[2025-10-20T16:23:48.013+0000] {taskinstance.py:1323} INFO - Marking task as UP_FOR_RETRY. dag_id=Airflow_Lab1_HeartDisease, task_id=load_data, execution_date=20251020T162346, start_date=20251020T162347, end_date=20251020T162348
[2025-10-20T16:23:48.018+0000] {standard_task_runner.py:105} ERROR - Failed to execute job 19 for task load_data ([Errno 2] No such file or directory: '/Users/gnanasudharsanashokumar/Downloads/Airflow_Labs/Lab_1/dags/data/heart_disease_uci.csv'; 85)
[2025-10-20T16:23:48.022+0000] {local_task_job.py:208} INFO - Task exited with return code 1
[2025-10-20T16:23:48.033+0000] {taskinstance.py:2578} INFO - 0 downstream tasks scheduled from follow-on schedule check
