[2025-10-20T16:42:13.177+0000] {taskinstance.py:1083} INFO - Dependencies all met for <TaskInstance: Airflow_Lab1_HeartDisease.data_preprocessing manual__2025-10-20T16:36:03.174714+00:00 [queued]>
[2025-10-20T16:42:13.182+0000] {taskinstance.py:1083} INFO - Dependencies all met for <TaskInstance: Airflow_Lab1_HeartDisease.data_preprocessing manual__2025-10-20T16:36:03.174714+00:00 [queued]>
[2025-10-20T16:42:13.183+0000] {taskinstance.py:1279} INFO - 
--------------------------------------------------------------------------------
[2025-10-20T16:42:13.183+0000] {taskinstance.py:1280} INFO - Starting attempt 2 of 2
[2025-10-20T16:42:13.183+0000] {taskinstance.py:1281} INFO - 
--------------------------------------------------------------------------------
[2025-10-20T16:42:13.189+0000] {taskinstance.py:1300} INFO - Executing <Task(PythonOperator): data_preprocessing> on 2025-10-20 16:36:03.174714+00:00
[2025-10-20T16:42:13.193+0000] {standard_task_runner.py:55} INFO - Started process 376 to run task
[2025-10-20T16:42:13.194+0000] {standard_task_runner.py:82} INFO - Running: ['***', 'tasks', 'run', 'Airflow_Lab1_HeartDisease', 'data_preprocessing', 'manual__2025-10-20T16:36:03.174714+00:00', '--job-id', '38', '--raw', '--subdir', 'DAGS_FOLDER/***.py', '--cfg-path', '/tmp/tmp2rdviio0']
[2025-10-20T16:42:13.195+0000] {standard_task_runner.py:83} INFO - Job 38: Subtask data_preprocessing
[2025-10-20T16:42:13.223+0000] {task_command.py:388} INFO - Running <TaskInstance: Airflow_Lab1_HeartDisease.data_preprocessing manual__2025-10-20T16:36:03.174714+00:00 [running]> on host 2354b3b035d7
[2025-10-20T16:42:13.250+0000] {taskinstance.py:1509} INFO - Exporting the following env vars:
AIRFLOW_CTX_DAG_OWNER=gnanasudharsan
AIRFLOW_CTX_DAG_ID=Airflow_Lab1_HeartDisease
AIRFLOW_CTX_TASK_ID=data_preprocessing
AIRFLOW_CTX_EXECUTION_DATE=2025-10-20T16:36:03.174714+00:00
AIRFLOW_CTX_TRY_NUMBER=2
AIRFLOW_CTX_DAG_RUN_ID=manual__2025-10-20T16:36:03.174714+00:00
[2025-10-20T16:42:13.259+0000] {logging_mixin.py:137} INFO - âœ… Data Loaded & Saved at /opt/***/dags/data/processed_heart_disease.csv
[2025-10-20T16:42:13.261+0000] {taskinstance.py:1768} ERROR - Task failed with exception
Traceback (most recent call last):
  File "/home/airflow/.local/lib/python3.7/site-packages/airflow/operators/python.py", line 175, in execute
    return_value = self.execute_callable()
  File "/home/airflow/.local/lib/python3.7/site-packages/airflow/operators/python.py", line 192, in execute_callable
    return self.python_callable(*self.op_args, **self.op_kwargs)
  File "/opt/airflow/dags/src/lab.py", line 34, in data_preprocessing
    scaled_data = scaler.fit_transform(df.drop('target', axis=1))
  File "/home/airflow/.local/lib/python3.7/site-packages/sklearn/base.py", line 852, in fit_transform
    return self.fit(X, **fit_params).transform(X)
  File "/home/airflow/.local/lib/python3.7/site-packages/sklearn/preprocessing/_data.py", line 416, in fit
    return self.partial_fit(X, y)
  File "/home/airflow/.local/lib/python3.7/site-packages/sklearn/preprocessing/_data.py", line 458, in partial_fit
    force_all_finite="allow-nan",
  File "/home/airflow/.local/lib/python3.7/site-packages/sklearn/base.py", line 566, in _validate_data
    X = check_array(X, **check_params)
  File "/home/airflow/.local/lib/python3.7/site-packages/sklearn/utils/validation.py", line 746, in check_array
    array = np.asarray(array, order=order, dtype=dtype)
  File "/home/airflow/.local/lib/python3.7/site-packages/pandas/core/generic.py", line 1993, in __array__
    return np.asarray(self._values, dtype=dtype)
ValueError: could not convert string to float: 'sex'
[2025-10-20T16:42:13.267+0000] {taskinstance.py:1323} INFO - Marking task as FAILED. dag_id=Airflow_Lab1_HeartDisease, task_id=data_preprocessing, execution_date=20251020T163603, start_date=20251020T164213, end_date=20251020T164213
[2025-10-20T16:42:13.273+0000] {standard_task_runner.py:105} ERROR - Failed to execute job 38 for task data_preprocessing (could not convert string to float: 'sex'; 376)
[2025-10-20T16:42:13.291+0000] {local_task_job.py:208} INFO - Task exited with return code 1
[2025-10-20T16:42:13.305+0000] {taskinstance.py:2578} INFO - 0 downstream tasks scheduled from follow-on schedule check
